事实证明，还有另一种实现方法try可以捕获这种性质的错误。

调整您的代码如下：

try:
    x = int(input("What's x?"))
except ValueError:
    print("x is not an integer")
else:
    print(f"x is {x}")
请注意，如果没有发生异常，它将运行 中的代码块else。运行python number.py并提供50，您会注意到结果将被打印。再试一次，这次提供cat，您会注意到程序现在捕获了错误。

考虑改进我们的代码，请注意我们对用户有点粗鲁。如果我们的用户不合作，我们目前只会结束我们的程序。考虑一下我们如何使用循环来提示用户x，如果他们不再提示！按如下方式改进您的代码：

while True:
    try:
        x = int(input("What's x?"))
    except ValueError:
        print("x is not an integer")
    else:
        break

print(f"x is {x}")
请注意，这while True将永远循环。如果用户成功提供了正确的输入，我们就可以中断循环，然后打印输出。现在，输入错误的用户将被要求再次输入。




我们可以使我们的代码不会警告用户，而只是通过修改代码来重新询问他们我们的提示问题，如下所示：

def main():
    x = get_int()
    print(f"x is {x}")


def get_int():
    while True:
        try:
            return int(input("What's x?"))
        except ValueError:
            pass


main()
请注意，我们的代码仍然可以运行，但不会重复通知用户他们的错误。在某些情况下，您需要让用户非常清楚正在产生什么错误。其他时候，您可能会决定只是想再次询问他们的意见。










